Traceback (most recent call last):
  File "/Users/glenn/miniconda3/lib/python3.12/site-packages/jupyter_cache/executors/utils.py", line 58, in single_nb_execution
    executenb(
  File "/Users/glenn/miniconda3/lib/python3.12/site-packages/nbclient/client.py", line 1305, in execute
    return NotebookClient(nb=nb, resources=resources, km=km, **kwargs).execute()
           ^^^^^^^^^^^^^^^^^^^^^^^^^^^^^^^^^^^^^^^^^^^^^^^^^^^^^^^^^^^^^^^^^^^^^
  File "/Users/glenn/miniconda3/lib/python3.12/site-packages/jupyter_core/utils/__init__.py", line 165, in wrapped
    return loop.run_until_complete(inner)
           ^^^^^^^^^^^^^^^^^^^^^^^^^^^^^^
  File "/Users/glenn/miniconda3/lib/python3.12/asyncio/base_events.py", line 685, in run_until_complete
    return future.result()
           ^^^^^^^^^^^^^^^
  File "/Users/glenn/miniconda3/lib/python3.12/site-packages/nbclient/client.py", line 705, in async_execute
    await self.async_execute_cell(
  File "/Users/glenn/miniconda3/lib/python3.12/site-packages/nbclient/client.py", line 1058, in async_execute_cell
    await self._check_raise_for_error(cell, cell_index, exec_reply)
  File "/Users/glenn/miniconda3/lib/python3.12/site-packages/nbclient/client.py", line 914, in _check_raise_for_error
    raise CellExecutionError.from_cell_and_msg(cell, exec_reply_content)
nbclient.exceptions.CellExecutionError: An error occurred while executing the following cell:
------------------
from shapely.geometry import Point
import geopandas
import pandas

df = pandas.read_csv("fastmerker.csv")
# Kolonnene fÃ¥r mellomromm i starten av navnet Â¯\_(ãƒ„)_/Â¯
geometry = geopandas.points_from_xy(df["     easting"], df["    northing"])
crs = {'init': 'epsg:25832'} #http://www.spatialreference.org/ref/epsg/25832/
geo_df = geopandas.GeoDataFrame(df, crs=crs, geometry=geometry)
geo_df.explore(marker_kwds=dict(radius=5, fill=True),
                color="red",
                popup=["name", "     easting", "    northing"])
------------------


[0;31m---------------------------------------------------------------------------[0m
[0;31mModuleNotFoundError[0m                       Traceback (most recent call last)
Cell [0;32mIn[1], line 1[0m
[0;32m----> 1[0m [38;5;28;01mfrom[39;00m [38;5;21;01mshapely[39;00m[38;5;21;01m.[39;00m[38;5;21;01mgeometry[39;00m [38;5;28;01mimport[39;00m Point
[1;32m      2[0m [38;5;28;01mimport[39;00m [38;5;21;01mgeopandas[39;00m
[1;32m      3[0m [38;5;28;01mimport[39;00m [38;5;21;01mpandas[39;00m

[0;31mModuleNotFoundError[0m: No module named 'shapely'

