Traceback (most recent call last):
  File "/Users/glenn/miniconda3/lib/python3.11/site-packages/jupyter_cache/executors/utils.py", line 58, in single_nb_execution
    executenb(
  File "/Users/glenn/miniconda3/lib/python3.11/site-packages/nbclient/client.py", line 1305, in execute
    return NotebookClient(nb=nb, resources=resources, km=km, **kwargs).execute()
           ^^^^^^^^^^^^^^^^^^^^^^^^^^^^^^^^^^^^^^^^^^^^^^^^^^^^^^^^^^^^^^^^^^^^^
  File "/Users/glenn/miniconda3/lib/python3.11/site-packages/jupyter_core/utils/__init__.py", line 165, in wrapped
    return loop.run_until_complete(inner)
           ^^^^^^^^^^^^^^^^^^^^^^^^^^^^^^
  File "/Users/glenn/miniconda3/lib/python3.11/asyncio/base_events.py", line 654, in run_until_complete
    return future.result()
           ^^^^^^^^^^^^^^^
  File "/Users/glenn/miniconda3/lib/python3.11/site-packages/nbclient/client.py", line 705, in async_execute
    await self.async_execute_cell(
  File "/Users/glenn/miniconda3/lib/python3.11/site-packages/nbclient/client.py", line 1058, in async_execute_cell
    await self._check_raise_for_error(cell, cell_index, exec_reply)
  File "/Users/glenn/miniconda3/lib/python3.11/site-packages/nbclient/client.py", line 914, in _check_raise_for_error
    raise CellExecutionError.from_cell_and_msg(cell, exec_reply_content)
nbclient.exceptions.CellExecutionError: An error occurred while executing the following cell:
------------------
import csv
from numpy import mean, std, array

csv_file = 'data.csv'

def read_csv(file_name):
    with open(file_name, 'r') as file:
        line = csv.reader(file)
        data = list(line)
    return data

def compute_mean(data):
    data = array(data)
    data = data[:,1:].astype(float)
    return mean(data, axis=0)

def compute_std(data):
    data = array(data)
    data = data[:,1:].astype(float)
    return std(data, axis=0)

# Test funksjon
data = read_csv(csv_file)
print('Gjennomsnitt: ', compute_mean(data))
print('Standardavvik: ', compute_std(data))
------------------


[0;31m---------------------------------------------------------------------------[0m
[0;31mFileNotFoundError[0m                         Traceback (most recent call last)
Cell [0;32mIn[2], line 23[0m
[1;32m     20[0m     [38;5;28;01mreturn[39;00m std(data, axis[38;5;241m=[39m[38;5;241m0[39m)
[1;32m     22[0m [38;5;66;03m# Test funksjon[39;00m
[0;32m---> 23[0m data [38;5;241m=[39m read_csv(csv_file)
[1;32m     24[0m [38;5;28mprint[39m([38;5;124m'[39m[38;5;124mGjennomsnitt: [39m[38;5;124m'[39m, compute_mean(data))
[1;32m     25[0m [38;5;28mprint[39m([38;5;124m'[39m[38;5;124mStandardavvik: [39m[38;5;124m'[39m, compute_std(data))

Cell [0;32mIn[2], line 7[0m, in [0;36mread_csv[0;34m(file_name)[0m
[1;32m      6[0m [38;5;28;01mdef[39;00m [38;5;21mread_csv[39m(file_name):
[0;32m----> 7[0m     [38;5;28;01mwith[39;00m [38;5;28mopen[39m(file_name, [38;5;124m'[39m[38;5;124mr[39m[38;5;124m'[39m) [38;5;28;01mas[39;00m file:
[1;32m      8[0m         line [38;5;241m=[39m csv[38;5;241m.[39mreader(file)
[1;32m      9[0m         data [38;5;241m=[39m [38;5;28mlist[39m(line)

File [0;32m~/miniconda3/lib/python3.11/site-packages/IPython/core/interactiveshell.py:324[0m, in [0;36m_modified_open[0;34m(file, *args, **kwargs)[0m
[1;32m    317[0m [38;5;28;01mif[39;00m file [38;5;129;01min[39;00m {[38;5;241m0[39m, [38;5;241m1[39m, [38;5;241m2[39m}:
[1;32m    318[0m     [38;5;28;01mraise[39;00m [38;5;167;01mValueError[39;00m(
[1;32m    319[0m         [38;5;124mf[39m[38;5;124m"[39m[38;5;124mIPython won[39m[38;5;124m'[39m[38;5;124mt let you open fd=[39m[38;5;132;01m{[39;00mfile[38;5;132;01m}[39;00m[38;5;124m by default [39m[38;5;124m"[39m
[1;32m    320[0m         [38;5;124m"[39m[38;5;124mas it is likely to crash IPython. If you know what you are doing, [39m[38;5;124m"[39m
[1;32m    321[0m         [38;5;124m"[39m[38;5;124myou can use builtins[39m[38;5;124m'[39m[38;5;124m open.[39m[38;5;124m"[39m
[1;32m    322[0m     )
[0;32m--> 324[0m [38;5;28;01mreturn[39;00m io_open(file, [38;5;241m*[39margs, [38;5;241m*[39m[38;5;241m*[39mkwargs)

[0;31mFileNotFoundError[0m: [Errno 2] No such file or directory: 'data.csv'

